<?xml version="1.0"?>
<robot name="inspector_bot" xmlns:xacro="http://www.ros.org/wiki/xacro">

  <xacro:property name="chassis_length" value="0.5"/>
  <xacro:property name="chassis_width"  value="0.3"/>
  <xacro:property name="chassis_height" value="0.2"/>
  <xacro:property name="chassis_mass"   value="15.0"/> 
  <xacro:property name="wheel_radius"   value="0.1"/>
  <xacro:property name="wheel_length"   value="0.04"/>
  <xacro:property name="wheel_ygap"     value="0.02"/>
  <xacro:property name="wheel_mass"     value="1.5"/>  
  <xacro:property name="ground_clearance" value="${wheel_radius}"/>
  <xacro:property name="caster_radius" value="${ground_clearance / 2}"/>

  <xacro:macro name="box_inertia" params="m l w h">
    <inertial>
      <origin xyz="0 0 0" rpy="0 0 0"/>
      <mass value="${m}"/>
      <inertia ixx="${(1/12) * m * (w*w + h*h)}" ixy="0.0" ixz="0.0"
               iyy="${(1/12) * m * (l*l + h*h)}" iyz="0.0"
               izz="${(1/12) * m * (l*l + w*w)}"/>
    </inertial>
  </xacro:macro>

  <xacro:macro name="cylinder_inertia" params="m r h">
    <inertial>
      <origin xyz="0 0 0" rpy="0 0 0"/>
      <mass value="${m}"/>
      <inertia ixx="${(1/12) * m * (3*r*r + h*h)}" ixy="0.0" ixz="0.0"
               iyy="${(1/12) * m * (3*r*r + h*h)}" iyz="0.0"
               izz="${(1/2) * m * r*r}"/>
    </inertial>
  </xacro:macro>

  <link name="base_footprint"/>

  <joint name="base_footprint_joint" type="fixed">
    <parent link="base_footprint"/>
    <child link="base_link"/>
    <origin xyz="0 0 0" rpy="0 0 0"/>
  </joint>

  <link name="base_link">
    <visual>
      <origin xyz="0 0 ${ground_clearance + (chassis_height/2)}" rpy="0 0 0"/>
      <geometry><box size="${chassis_length} ${chassis_width} ${chassis_height}"/></geometry>
      <material name="blue"><color rgba="0.1 0.1 0.8 1.0"/></material>
    </visual>
    <collision>
      <origin xyz="0 0 ${ground_clearance + (chassis_height/2)}" rpy="0 0 0"/>
      <geometry><box size="${chassis_length} ${chassis_width} ${chassis_height}"/></geometry>
    </collision>
    <xacro:box_inertia m="${chassis_mass}" l="${chassis_length}" w="${chassis_width}" h="${chassis_height}"/>
  </link>

  <xacro:macro name="wheel" params="prefix y_reflect">
    <link name="${prefix}_wheel">
      <visual>
        <geometry><cylinder radius="${wheel_radius}" length="${wheel_length}"/></geometry>
        <material name="black"><color rgba="0.0 0.0 0.0 1.0"/></material>
      </visual>
      <collision>
        <geometry><cylinder radius="${wheel_radius}" length="${wheel_length}"/></geometry>
      </collision>
      <xacro:cylinder_inertia m="${wheel_mass}" r="${wheel_radius}" h="${wheel_length}"/>
    </link>

    <joint name="${prefix}_wheel_joint" type="continuous">
      <parent link="base_link"/>
      <child link="${prefix}_wheel"/>
      <origin xyz="0 ${(chassis_width/2 + wheel_length/2) * y_reflect} ${wheel_radius}" rpy="-${pi/2} 0 0"/>
      <axis xyz="0 0 1"/>
      <dynamics damping="0.1" friction="0.1"/>
    </joint>
  </xacro:macro>

  <xacro:wheel prefix="left"  y_reflect="1" />
  <xacro:wheel prefix="right" y_reflect="-1" />

  <link name="laser_frame">
    <visual>
      <geometry>
        <cylinder radius="0.05" length="0.04"/>
      </geometry>
      <material name="black"/>
    </visual>
    <collision>
      <geometry>
        <cylinder radius="0.05" length="0.04"/>
      </geometry>
    </collision>
    <inertial>
      <mass value="0.1"/>
      <inertia ixx="0.0001" ixy="0.0" ixz="0.0" iyy="0.0001" iyz="0.0" izz="0.0001"/>
    </inertial>
  </link>

  <joint name="laser_joint" type="fixed">
    <parent link="base_link"/>
    <child link="laser_frame"/>
    <origin xyz="0.2 0.0 ${ground_clearance + chassis_height}" rpy="0 0 0"/>
  </joint>

  <link name="camera_link">
    <visual>
      <geometry><box size="0.02 0.05 0.03"/></geometry>
      <material name="black"/>
    </visual>
    <collision>
      <geometry><box size="0.02 0.05 0.03"/></geometry>
    </collision>
    <inertial>
      <mass value="0.05"/>
      <inertia ixx="0.0001" ixy="0" ixz="0" iyy="0.0001" iyz="0" izz="0.0001"/>
    </inertial>
  </link>

  <joint name="camera_joint" type="fixed">
    <parent link="base_link"/>
    <child link="camera_link"/>
    <origin xyz="${chassis_length/2} 0.0 ${chassis_height/2 + 0.05}" rpy="0 0 0"/>
  </joint>

  <link name="caster_wheel">
    <visual>
      <geometry><sphere radius="${caster_radius}"/></geometry>
      <material name="black"/>
    </visual>
    <collision>
      <geometry><sphere radius="${caster_radius}"/></geometry>
    </collision>
    <inertial>
      <mass value="0.5"/>
      <inertia ixx="0.001" ixy="0.0" ixz="0.0" iyy="0.001" iyz="0.0" izz="0.001"/>
    </inertial>
  </link>

  <joint name="caster_wheel_joint" type="fixed">
    <parent link="base_link"/>
    <child link="caster_wheel"/>
    <origin xyz="-${chassis_length/3} 0.0 ${caster_radius}" rpy="0 0 0"/>
  </joint>

  <ros2_control name="GazeboSimSystem" type="system">
    
    <hardware>
      <plugin>gz_ros2_control/GazeboSimSystem</plugin>
    </hardware>

    <joint name="left_wheel_joint">
      <command_interface name="velocity">
        <param name="min">-10</param>
        <param name="max">10</param>
      </command_interface>
      <state_interface name="position"/>
      <state_interface name="velocity"/>
    </joint>

    <joint name="right_wheel_joint">
      <command_interface name="velocity">
        <param name="min">-10</param>
        <param name="max">10</param>
      </command_interface>
      <state_interface name="position"/>
      <state_interface name="velocity"/>
    </joint>

  </ros2_control>

  <gazebo reference="base_link">
    <material>Gazebo/Blue</material>
  </gazebo>

  <gazebo reference="left_wheel">
    <mu1>1.0</mu1>
    <mu2>1.0</mu2>
    <material>Gazebo/Black</material>
  </gazebo>

  <gazebo reference="right_wheel">
    <mu1>1.0</mu1>
    <mu2>1.0</mu2>
    <material>Gazebo/Black</material>
  </gazebo>

  <gazebo reference="caster_wheel">
    <mu1>0.0</mu1>
    <mu2>0.0</mu2>
    <material>Gazebo/Black</material>
  </gazebo>

  <gazebo>
    <plugin filename="gz_ros2_control-system" name="gz_ros2_control::GazeboSimROS2ControlPlugin">
      <parameters>$(find inspector_bot)/config/controllers.yaml</parameters>
    
    </plugin>
  </gazebo>
  
  <gazebo reference="laser_frame">
    <material>Gazebo/Black</material>
    <sensor name="laser" type="gpu_lidar">
      <pose>0 0 0 0 0 0</pose>
      <visualize>true</visualize>
      <update_rate>10</update_rate>
      <topic>scan</topic>
      <gz_frame_id>laser_frame</gz_frame_id>
      <lidar>
        <scan>
          <horizontal>
            <samples>360</samples>
            <resolution>1</resolution>
            <min_angle>-3.14159</min_angle>
            <max_angle>3.14159</max_angle>
          </horizontal>
        </scan>
        <range>
          <min>0.3</min>
          <max>12.0</max>
          <resolution>0.01</resolution>
        </range>
      </lidar>
    </sensor>
  </gazebo>

  <gazebo reference="camera_link">
    <sensor name="inspection_camera" type="rgbd_camera">
      <camera>
        <horizontal_fov>1.047</horizontal_fov>
        <image>
          <width>1280</width>
          <height>720</height>
          <format>R8G8B8</format>
        </image>
        <clip>
          <near>0.1</near>
          <far>10.0</far>
        </clip>
      </camera>
      <always_on>1</always_on>
      <update_rate>15</update_rate>
      <visualize>true</visualize>
      <topic>camera</topic>
      <gz_frame_id>camera_link</gz_frame_id>
    </sensor>
  </gazebo>

  </robot>